---
layout: single
title: 'Exception Handling'
typora-root-url: ../
categories: Python.07.예외처리
tag: Python
toc: true
---

# Exception Handling

Exception이 발생되어 프로그램이 더이상 실행될 수 없는 상황을 처리(handling)해서 정상화 시키는 작업

###  try, except 구문

```python
try:
    Exception 발생가능한 코드 블록
except [Exception클래스 이름 [as 변수]] :
    처리 코드   
```

- **try block**
    - Exception 발생 가능성 있는 코드와 그 코드와 연결된 코드들을 블록으로 묶는다.
        - 연결된 코드란 Exception이 발생 안해야만 실행되는 코드를 말한다.
- **except block**
    - 발생한 Exception을 처리하는 코드 블록을 작성한다.
        - try block의 코드를 실행하다 exception이 발생하면 except block이 실행된다. Exception이 발생하지 않으면 실행되지 않는다.


```python
print("프로그램 시작")    # 1

num = int(input("정수:"))# 2.Exception 발생 가능성이 있는 코드.
result = 10 // num       # 3
print("결과:", result)   # 4
   
print("프로그램 종료") 
```

    프로그램 시작
    정수:123
    결과: 0
    프로그램 종료



```python
# Exception Error 하나만 처리
print("프로그램 시작")    # 1

try:
    num = int(input("정수:"))#  2.Exception 발생 가능성이 있는 코드.
    result = 10 // num       # 3. Exception 발생 가능성이 있는 코드.
    print("결과:", result)   # 4
except:
    print("실행도중 문제가 발생했습니다. 일단 처리했습니다.")  # EH
    
    
print("프로그램 종료 ==> 다음작업")    # 5


# 정상흐름: 1, 2, 3, 4, 5
# 2번에서 Exception 발생: 1, 2(x), 3(x), 4(x), EH, 5
#      -> 1, EH, 5
# 3번에서 Exception 발생: 1. 2, 3(x), 4(x), EH, 
#      -> 1, 2, EH, 5
```

    프로그램 시작
    정수:0
    실행도중 문제가 발생했습니다. 일단 처리했습니다.
    프로그램 종료 ==> 다음작업



```python
# Exception 났을 때 클래스 이름을 정해줘야한다. => 클래스 : 파이썬 내장에 있는 에러 클래스 이름과 같이 넣어야함
## 에러 블륵은 그냥 실행을 안하고 그냥 넘어감 ( 기록 남음 )
### 에러가 난 블록은 출력을 그만하고 다음 코드블록으로 넘어감 ( 해결이 안됨 )
print('프로그램 시작') # 1

try:
    num = int(input('점수:')) # 2 Excetion 발생 가능성이 있는 코드,
    result = 10 // num # 3 Excetion 발생 가능성 있는 코드 
    print('결과:',result) # 4
    print('결과2:', result2) # NameError Exception 발생 
except ValueError as ve: # ValueError 를 처리하는 Block
    print('정수로 변환을 못했습니다.- ValueError 발생 -') # EH 1 ( Excetion Handling )
    print('ve 변수출력:',ve)
except ZeroDivisionError as ze: # ZeroDivisionError 를 처리하는 Block
    print('0으로는 못나눕니다. - ZeroDivisionError 발생 -') # EH 2 ( Excetion Handling )
    print('ze 변수출력:',ze)
except Exception as e : # 두 Excetion을 제외한 나머지 Excetion 을 처리.
    print('실행도중 문제가 발생했습니다. 일단 처리했습니다') # EH 3 ( Excetion Handling )
    print('e 변수출력:',e)
print('프로그램 종료 ==> 다음작업') # 5

# Try -> ValueError 발생 : 1, EH1, 5
# Try -> ZeroDivisionEroor 발생 : 1, 2, EH2, 5
# Try -> ValueError, ZeroDivisionError 제외된 exception 발생( NameError )
#                  1, 2, 3, 4, EH3, 5
```

    프로그램 시작
    점수:123
    결과: 0
    실행도중 문제가 발생했습니다. 일단 처리했습니다
    e 변수출력: name 'result2' is not defined
    프로그램 종료 ==> 다음작업


### finally 구문

- 예외 발생여부, 처리 여부와 관계없이 무조건 실행되는 코드블록
    - try 구문에 **반드시 실행되야 하는 코드블록을 작성할때 사용한다.**
- finally 는 except 보다 먼저 올 수 없다.
    - 구문순서
        1. try - except - finally
        1. try - except
        1. try - finally


```python

print('시작')
try:
    print(1)
    a= 10 / 1
    print(2)
#     b = int('aa')
except ValueError:
    print(3)
# 도중에 무조건 에러가 나도 Finally를 실행
finally:
    print('무조건 실행한다.')
print('종료')

```

    시작
    1
    2
    무조건 실행한다.
    종료



```python
try:
    a = int(input())
except:
    print("예외발생")
else:
    print(a + 10)
finally:
    print("무조건실행할 코드")
```

    aaaa
    예외발생
    무조건실행할 코드
